Workbook
Name Slicer_Cabang: #N/A
Name Slicer_Divisi: #N/A

Sheet Dashboard
L6: Date Cut Off | N6: =NOW() -> 46245.856
I20: No | J20: Nama Pegawai | L20: Cabang | N20: Skor KPI
I21: =IF(J21<>"",1,"") -> 1 | J21: =IF(Sheet2!R12<>"",Sheet2!R12,"") -> Iman | L21: =IF(Sheet2!S12<>"",Sheet2!S12,"") -> Jakarta | N21: =IF(Sheet2!T12<>"",Sheet2!T12,"") -> 2.1558333
I22: =IF(J22<>"",I21+1,"") -> 2 | J22: =IF(Sheet2!R13<>"",Sheet2!R13,"") -> Muni Ledia Astuti | L22: =IF(Sheet2!S13<>"",Sheet2!S13,"") -> Jakarta | N22: =IF(Sheet2!T13<>"",Sheet2!T13,"") -> 2.5175
I23: =IF(J23<>"",I22+1,"") -> 3 | J23: =IF(Sheet2!R14<>"",Sheet2!R14,"") -> Hanasira Afifa | L23: =IF(Sheet2!S14<>"",Sheet2!S14,"") -> Bandung | N23: =IF(Sheet2!T14<>"",Sheet2!T14,"") -> 2.7816667
I24: =IF(J24<>"",I23+1,"") -> 4 | J24: =IF(Sheet2!R15<>"",Sheet2!R15,"") -> Rizal Ermanto | L24: =IF(Sheet2!S15<>"",Sheet2!S15,"") -> Jakarta | N24: =IF(Sheet2!T15<>"",Sheet2!T15,"") -> 2.8933333
I25: =IF(J25<>"",I24+1,"") -> 5 | J25: =IF(Sheet2!R16<>"",Sheet2!R16,"") -> Peter Sulaeman | L25: =IF(Sheet2!S16<>"",Sheet2!S16,"") -> Jakarta | N25: =IF(Sheet2!T16<>"",Sheet2!T16,"") -> 2.9991667
I26: =IF(J26<>"",I25+1,"") -> 6 | J26: =IF(Sheet2!R17<>"",Sheet2!R17,"") -> Citra Mega Lestari | L26: =IF(Sheet2!S17<>"",Sheet2!S17,"") -> Bandung | N26: =IF(Sheet2!T17<>"",Sheet2!T17,"") -> 3.0375
I27: =IF(J27<>"",I26+1,"") -> 7 | J27: =IF(Sheet2!R18<>"",Sheet2!R18,"") -> Yulia Nur Safitri | L27: =IF(Sheet2!S18<>"",Sheet2!S18,"") -> Jakarta | N27: =IF(Sheet2!T18<>"",Sheet2!T18,"") -> 3.0408333
I28: =IF(J28<>"",I27+1,"") -> 8 | J28: =IF(Sheet2!R19<>"",Sheet2!R19,"") -> Yolanda Novitri Setiawan | L28: =IF(Sheet2!S19<>"",Sheet2!S19,"") -> Jakarta | N28: =IF(Sheet2!T19<>"",Sheet2!T19,"") -> 3.1291667
I29: =IF(J29<>"",I28+1,"") -> 9 | J29: =IF(Sheet2!R20<>"",Sheet2!R20,"") -> Ferdinand Is Suhendra | L29: =IF(Sheet2!S20<>"",Sheet2!S20,"") -> Jakarta | N29: =IF(Sheet2!T20<>"",Sheet2!T20,"") -> 3.1541667
I30: =IF(J30<>"",I29+1,"") -> 10 | J30: =IF(Sheet2!R21<>"",Sheet2!R21,"") -> Agung saputra | L30: =IF(Sheet2!S21<>"",Sheet2!S21,"") -> Jakarta | N30: =IF(Sheet2!T21<>"",Sheet2!T21,"") -> 3.2725
I31: =IF(J31<>"",I30+1,"") -> 11 | J31: =IF(Sheet2!R22<>"",Sheet2!R22,"") -> Ana Muslimah | L31: =IF(Sheet2!S22<>"",Sheet2!S22,"") -> Jakarta | N31: =IF(Sheet2!T22<>"",Sheet2!T22,"") -> 3.405
I32: =IF(J32<>"",I31+1,"") -> 12 | J32: =IF(Sheet2!R23<>"",Sheet2!R23,"") -> Nur Devi Yusiawati Gumelar | L32: =IF(Sheet2!S23<>"",Sheet2!S23,"") -> Jakarta | N32: =IF(Sheet2!T23<>"",Sheet2!T23,"") -> 3.5925
I33: =IF(J33<>"",I32+1,"") -> 13 | J33: =IF(Sheet2!R24<>"",Sheet2!R24,"") -> Dwi Wira Surachandra | L33: =IF(Sheet2!S24<>"",Sheet2!S24,"") -> Bandung | N33: =IF(Sheet2!T24<>"",Sheet2!T24,"") -> 3.6783333

Sheet Sheet2
B3: Jumlah Karyawan
B4: 122
B11: Row Labels | C11: Jumlah Karyawan | F11: Row Labels | G11: Jumlah Karyawan | J11: Row Labels | K11: Jumlah Karyawan | N11: Row Labels | O11: Jumlah Karyawan | R11: Nama Pegawai | S11: Cabang | T11: Sum of Average
B12: Contract | C12: 28 | F12: Laki-laki | G12: 48 | J12: Baby Boomer | K12: 1 | N12: Low | O12: 5 | R12: Iman | S12: Jakarta | T12: 2.1558333
B13: Outsource | C13: 2 | F13: Perempuan | G13: 74 | J13: Gen X | K13: 36 | N13: Med | O13: 8 | R13: Muni Ledia Astuti | S13: Jakarta | T13: 2.5175
B14: Permanent | C14: 92 | F14: Grand Total | G14: 122 | J14: Gen Y | K14: 83 | N14: Grand Total | O14: 13 | R14: Hanasira Afifa | S14: Bandung | T14: 2.7816667
B15: Grand Total | C15: 122 | J15: Gen Z | K15: 2 | R15: Rizal Ermanto | S15: Jakarta | T15: 2.8933333
J16: Grand Total | K16: 122 | R16: Peter Sulaeman | S16: Jakarta | T16: 2.9991667
R17: Citra Mega Lestari | S17: Bandung | T17: 3.0375
R18: Yulia Nur Safitri | S18: Jakarta | T18: 3.0408333
R19: Yolanda Novitri Setiawan | S19: Jakarta | T19: 3.1291667
R20: Ferdinand Is Suhendra | S20: Jakarta | T20: 3.1541667
R21: Agung saputra | S21: Jakarta | T21: 3.2725
R22: Ana Muslimah | S22: Jakarta | T22: 3.405
R23: Nur Devi Yusiawati Gumelar | S23: Jakarta | T23: 3.5925
R24: Dwi Wira Surachandra | S24: Bandung | T24: 3.6783333

Sheet Sheet1
A1: NIP | B1: Nama Pegawai | C1: Divisi | D1: Level | E1: Cabang | F1: Status | G1: Jenis Kelamin | H1: Tanggal Lahir | I1: Mulai Kerja | J1: Usia | K1: Generasi Kerja | L1: Pendidikan | M1: Jan | N1: Feb | O1: Mar | P1: Apr | Q1: May | R1: Jun | S1: Jul | T1: Aug | U1: Sep | V1: Oct | W1: Nov | X1: Dec | Y1: Average | Z1: Kinerja
A2: 116137 | B2: Agnes Dirgantini Hakim | C2: Bisnis | D2: Staff | E2: Jakarta | F2: Permanent | G2: Perempuan | H2: 33239 | I2: 42856 | J2: =DATEDIF(Table2[[#This Row],[Tanggal Lahir]],NOW(),"Y") -> 35 | K2: =IF(Table2[[#This Row],[Usia]]<25,"Gen Z",IF(Table2[[#This Row],[Usia]]<40,"Gen Y",IF(Table2[[#This Row],[Usia]]<56,"Gen X",IF(Table2[[#This Row],[Usia]]>=56,"Baby Boomer")))) -> Gen Y | L2: Diploma | M2: 4.94 | N2: 4.59 | O2: 1.74 | P2: 4.25 | Q2: 3.85 | R2: 1.26 | S2: 1.52 | T2: 2.07 | U2: 2.15 | V2: 4.75 | W2: 2.17 | X2: 3.51 | Y2: =AVERAGE(Table2[[#This Row],[Jan]:[Dec]]) -> 3.0666667 | Z2: =IF(Table2[[#This Row],[Average]]<3,"Low",IF(Table2[[#This Row],[Average]]<=4,"Med",IF(Table2[[#This Row],[Average]]>4,"High"))) -> Med
A3: 116857 | B3: Moch Adnand Heriansyah | C3: Bisnis | D3: Staff | E3: Bandung | F3: Permanent | G3: Laki-laki | H3: 34456 | I3: 42826 | J3: =DATEDIF(Table2[[#This Row],[Tanggal Lahir]],NOW(),"Y") -> 32 | K3: =IF(Table2[[#This Row],[Usia]]<25,"Gen Z",IF(Table2[[#This Row],[Usia]]<40,"Gen Y",IF(Table2[[#This Row],[Usia]]<56,"Gen X",IF(Table2[[#This Row],[Usia]]>=56,"Baby Boomer")))) -> Gen Y | L3: D3 | M3: 3.13 | N3: 2.22 | O3: 2.51 | P3: 4.25 | Q3: 4.55 | R3: 4.98 | S3: 2.29 | T3: 1.42 | U3: 1.98 | V3: 3.95 | W3: 3.75 | X3: 3.67 | Y3: =AVERAGE(Table2[[#This Row],[Jan]:[Dec]]) -> 3.225 | Z3: =IF(Table2[[#This Row],[Average]]<3,"Low",IF(Table2[[#This Row],[Average]]<=4,"Med",IF(Table2[[#This Row],[Average]]>4,"High"))) -> Med
A4: 117360 | B4: Anjani Meilawati Dewi | C4: Support | D4: Staff | E4: Jakarta | F4: Permanent | G4: Perempuan | H4: 31471 | I4: 42065 | J4: =DATEDIF(Table2[[#This Row],[Tanggal Lahir]],NOW(),"Y") -> 40 | K4: =IF(Table2[[#This Row],[Usia]]<25,"Gen Z",IF(Table2[[#This Row],[Usia]]<40,"Gen Y",IF(Table2[[#This Row],[Usia]]<56,"Gen X",IF(Table2[[#This Row],[Usia]]>=56,"Baby Boomer")))) -> Gen X | L4: S1 | M4: 1.19 | N4: 1.64 | O4: 4.16 | P4: 1.09 | Q4: 3.32 | R4: 3.52 | S4: 4.2 | T4: 3.23 | U4: 2.35 | V4: 1.52 | W4: 1.37 | X4: 2.12 | Y4: =AVERAGE(Table2[[#This Row],[Jan]:[Dec]]) -> 2.4758333 | Z4: =IF(Table2[[#This Row],[Average]]<3,"Low",IF(Table2[[#This Row],[Average]]<=4,"Med",IF(Table2[[#This Row],[Average]]>4,"High"))) -> Low
A5: 120236 | B5: Muhammad Itsal Septian Rahman | C5: Bisnis | D5: Staff | E5: Bandung | F5: Contract | G5: Laki-laki | H5: 34853 | I5: 44628 | J5: =DATEDIF(Table2[[#This Row],[Tanggal Lahir]],NOW(),"Y") -> 31 | K5: =IF(Table2[[#This Row],[Usia]]<25,"Gen Z",IF(Table2[[#This Row],[Usia]]<40,"Gen Y",IF(Table2[[#This Row],[Usia]]<56,"Gen X",IF(Table2[[#This Row],[Usia]]>=56,"Baby Boomer")))) -> Gen Y | L5: D3 | M5: 2.12 | N5: 1.68 | O5: 3.41 | P5: 4.62 | Q5: 2.33 | R5: 3.95 | S5: 3.56 | T5: 2.49 | U5: 3.84 | V5: 1.86 | W5: 3.22 | X5: 1.9 | Y5: =AVERAGE(Table2[[#This Row],[Jan]:[Dec]]) -> 2.915 | Z5: =IF(Table2[[#This Row],[Average]]<3,"Low",IF(Table2[[#This Row],[Average]]<=4,"Med",IF(Table2[[#This Row],[Average]]>4,"High"))) -> Low
A6: 129289 | B6: Muhammad Doddy Djakaria | C6: Bisnis | D6: Staff | E6: Bandung | F6: Permanent | G6: Laki-laki | H6: 30282 | I6: 42552 | J6: =DATEDIF(Table2[[#This Row],[Tanggal Lahir]],NOW(),"Y") -> 43 | K6: =IF(Table2[[#This Row],[Usia]]<25,"Gen Z",IF(Table2[[#This Row],[Usia]]<40,"Gen Y",IF(Table2[[#This Row],[Usia]]<56,"Gen X",IF(Table2[[#This Row],[Usia]]>=56,"Baby Boomer")))) -> Gen X | L6: S1 | M6: 4.53 | N6: 2.9 | O6: 1.51 | P6: 1.8 | Q6: 4.52 | R6: 3.24 | S6: 2.59 | T6: 2.58 | U6: 3.25 | V6: 3.1 | W6: 2.91 | X6: 3.62 | Y6: =AVERAGE(Table2[[#This Row],[Jan]:[Dec]]) -> 3.0458333 | Z6: =IF(Table2[[#This Row],[Average]]<3,"Low",IF(Table2[[#This Row],[Average]]<=4,"Med",IF(Table2[[#This Row],[Average]]>4,"High"))) -> Med
A7: 129462 | B7: Novianti Warnerin | C7: Bisnis | D7: Officer | E7: Bandung | F7: Permanent | G7: Perempuan | H7: 32997 | I7: 42856 | J7: =DATEDIF(Table2[[#This Row],[Tanggal Lahir]],NOW(),"Y") -> 36 | K7: =IF(Table2[[#This Row],[Usia]]<25,"Gen Z",IF(Table2[[#This Row],[Usia]]<40,"Gen Y",IF(Table2[[#This Row],[Usia]]<56,"Gen X",IF(Table2[[#This Row],[Usia]]>=56,"Baby Boomer")))) -> Gen Y | L7: S1 | M7: 2.3 | N7: 2.76 | O7: 3.69 | P7: 3.25 | Q7: 2.6 | R7: 3.92 | S7: 5 | T7: 1.87 | U7: 4.37 | V7: 2.87 | W7: 2.57 | X7: 1.97 | Y7: =AVERAGE(Table2[[#This Row],[Jan]:[Dec]]) -> 3.0975 | Z7: =IF(Table2[[#This Row],[Average]]<3,"Low",IF(Table2[[#This Row],[Average]]<=4,"Med",IF(Table2[[#This Row],[Average]]>4,"High"))) -> Med
A8: 134130 | B8: Suci Ananda | C8: Bisnis | D8: Staff | E8: Jakarta | F8: Permanent | G8: Perempuan | H8: 33572 | I8: 41701 | J8: =DATEDIF(Table2[[#This Row],[Tanggal Lahir]],NOW(),"Y") -> 34 | K8: =IF(Table2[[#This Row],[Usia]]<25,"Gen Z",IF(Table2[[#This Row],[Usia]]<40,"Gen Y",IF(Table2[[#This Row],[Usia]]<56,"Gen X",IF(Table2[[#This Row],[Usia]]>=56,"Baby Boomer")))) -> Gen Y | L8: S1 | M8: 4.72 | N8: 3.68 | O8: 3.73 | P8: 3.21 | Q8: 3.51 | R8: 3.78 | S8: 3.58 | T8: 1.49 | U8: 4.49 | V8: 4.35 | W8: 4 | X8: 2.88 | Y8: =AVERAGE(Table2[[#This Row],[Jan]:[Dec]]) -> 3.6183333 | Z8: =IF(Table2[[#This Row],[Average]]<3,"Low",IF(Table2[[#This Row],[Average]]<=4,"Med",IF(Table2[[#This Row],[Average]]>4,"High"))) -> Med
A9: 135771 | B9: Nur Devi Yusiawati Gumelar | C9: Asset | D9: Staff | E9: Jakarta | F9: Permanent | G9: Perempuan | H9: 30433 | I9: 42917 | J9: =DATEDIF(Table2[[#This Row],[Tanggal Lahir]],NOW(),"Y") -> 43 | K9: =IF(Table2[[#This Row],[Usia]]<25,"Gen Z",IF(Table2[[#This Row],[Usia]]<40,"Gen Y",IF(Table2[[#This Row],[Usia]]<56,"Gen X",IF(Table2[[#This Row],[Usia]]>=56,"Baby Boomer")))) -> Gen X | L9: S1 | M9: 3.82 | N9: 3.92 | O9: 3.16 | P9: 4.45 | Q9: 3.58 | R9: 4.87 | S9: 2.5 | T9: 4.44 | U9: 4.45 | V9: 3.91 | W9: 1.95 | X9: 2.06 | Y9: =AVERAGE(Table2[[#This Row],[Jan]:[Dec]]) -> 3.5925 | Z9: =IF(Table2[[#This Row],[Average]]<3,"Low",IF(Table2[[#This Row],[Average]]<=4,"Med",IF(Table2[[#This Row],[Average]]>4,"High"))) -> Med
A10: 139299 | B10: Revina Sadiyyah Fatimah | C10: Bisnis | D10: Officer | E10: Bandung | F10: Permanent | G10: Perempuan | H10: 28672 | I10: 40147 | J10: =DATEDIF(Table2[[#This Row],[Tanggal Lahir]],NOW(),"Y") -> 48 | K10: =IF(Table2[[#This Row],[Usia]]<25,"Gen Z",IF(Table2[[#This Row],[Usia]]<40,"Gen Y",IF(Table2[[#This Row],[Usia]]<56,"Gen X",IF(Table2[[#This Row],[Usia]]>=56,"Baby Boomer")))) -> Gen X | L10: Diploma | M10: 2.25 | N10: 3 | O10: 2.04 | P10: 3.43 | Q10: 2.63 | R10: 1.98 | S10: 2.71 | T10: 2.68 | U10: 4.72 | V10: 2.6 | W10: 4.35 | X10: 2.1 | Y10: =AVERAGE(Table2[[#This Row],[Jan]:[Dec]]) -> 2.8741667 | Z10: =IF(Table2[[#This Row],[Average]]<3,"Low",IF(Table2[[#This Row],[Average]]<=4,"Med",IF(Table2[[#This Row],[Average]]>4,"High"))) -> Low
A11: 141347 | B11: Ckasinta Winda S | C11: Bisnis | D11: Staff | E11: Jakarta | F11: Permanent | G11: Perempuan | H11: 28322 | I11: 38598 | J11: =DATEDIF(Table2[[#This Row],[Tanggal Lahir]],NOW(),"Y") -> 49 | K11: =IF(Table2[[#This Row],[Usia]]<25,"Gen Z",IF(Table2[[#This Row],[Usia]]<40,"Gen Y",IF(Table2[[#This Row],[Usia]]<56,"Gen X",IF(Table2[[#This Row],[Usia]]>=56,"Baby Boomer")))) -> Gen X | L11: S1 | M11: 3.27 | N11: 1.56 | O11: 4.76 | P11: 1.24 | Q11: 3.7 | R11: 3.97 | S11: 3.63 | T11: 2.74 | U11: 3.04 | V11: 2.5 | W11: 2.73 | X11: 4.12 | Y11: =AVERAGE(Table2[[#This Row],[Jan]:[Dec]]) -> 3.105 | Z11: =IF(Table2[[#This Row],[Average]]<3,"Low",IF(Table2[[#This Row],[Average]]<=4,"Med",IF(Table2[[#This Row],[Average]]>4,"High"))) -> Med
A12: 144305 | B12: Nurfa Resti Aulia | C12: Bisnis | D12: Staff | E12: Jakarta | F12: Permanent | G12: Perempuan | H12: 32951 | I12: 43009 | J12: =DATEDIF(Table2[[#This Row],[Tanggal Lahir]],NOW(),"Y") -> 36 | K12: =IF(Table2[[#This Row],[Usia]]<25,"Gen Z",IF(Table2[[#This Row],[Usia]]<40,"Gen Y",IF(Table2[[#This Row],[Usia]]<56,"Gen X",IF(Table2[[#This Row],[Usia]]>=56,"Baby Boomer")))) -> Gen Y | L12: S1 | M12: 1.47 | N12: 3.31 | O12: 4.75 | P12: 1.18 | Q12: 4.72 | R12: 4.56 | S12: 4.51 | T12: 1.84 | U12: 3.07 | V12: 1.18 | W12: 1.97 | X12: 3.59 | Y12: =AVERAGE(Table2[[#This Row],[Jan]:[Dec]]) -> 3.0125 | Z12: =IF(Table2[[#This Row],[Average]]<3,"Low",IF(Table2[[#This Row],[Average]]<=4,"Med",IF(Table2[[#This Row],[Average]]>4,"High"))) -> Med
A13: 145284 | B13: Pinaandriyani | C13: Bisnis | D13: Staff | E13: Jakarta | F13: Permanent | G13: Perempuan | H13: 31488 | I13: 43040 | J13: =DATEDIF(Table2[[#This Row],[Tanggal Lahir]],NOW(),"Y") -> 40 | K13: =IF(Table2[[#This Row],[Usia]]<25,"Gen Z",IF(Table2[[#This Row],[Usia]]<40,"Gen Y",IF(Table2[[#This Row],[Usia]]<56,"Gen X",IF(Table2[[#This Row],[Usia]]>=56,"Baby Boomer")))) -> Gen X | L13: S1 | M13: 1.85 | N13: 1.74 | O13: 1.35 | P13: 2.16 | Q13: 4.49 | R13: 2.94 | S13: 1 | T13: 4.61 | U13: 1.94 | V13: 4.33 | W13: 3.37 | X13: 3.26 | Y13: =AVERAGE(Table2[[#This Row],[Jan]:[Dec]]) -> 2.7533333 | Z13: =IF(Table2[[#This Row],[Average]]<3,"Low",IF(Table2[[#This Row],[Average]]<=4,"Med",IF(Table2[[#This Row],[Average]]>4,"High"))) -> Low
... A51: 247252 | B51: Rendi Agus Tirtana | C51: Bisnis | D51: Staff | E51: Jakarta | F51: Permanent | G51: Laki-laki | H51: 33396 | I51: 41432 | J51: =DATEDIF(Table2[[#This Row],[Tanggal Lahir]],NOW(),"Y") -> 35 | K51: =IF(Table2[[#This Row],[Usia]]<25,"Gen Z",IF(Table2[[#This Row],[Usia]]<40,"Gen Y",IF(Table2[[#This Row],[Usia]]<56,"Gen X",IF(Table2[[#This Row],[Usia]]>=56,"Baby Boomer")))) -> Gen Y | L51: D3 | M51: 2.02 | N51: 2.93 | O51: 1.24 | P51: 4.85 | Q51: 3.88 | R51: 3.47 | S51: 4.39 | T51: 3.28 | U51: 3.79 | V51: 4.07 | W51: 2.5 | X51: 2.48 | Y51: =AVERAGE(Table2[[#This Row],[Jan]:[Dec]]) -> 3.2416667 | Z51: =IF(Table2[[#This Row],[Average]]<3,"Low",IF(Table2[[#This Row],[Average]]<=4,"Med",IF(Table2[[#This Row],[Average]]>4,"High"))) -> Med
A52: 247739 | B52: Kania Anisa Lestari | C52: Bisnis | D52: Staff | E52: Bandung | F52: Contract | G52: Perempuan | H52: 36496 | I52: 44973 | J52: =DATEDIF(Table2[[#This Row],[Tanggal Lahir]],NOW(),"Y") -> 26 | K52: =IF(Table2[[#This Row],[Usia]]<25,"Gen Z",IF(Table2[[#This Row],[Usia]]<40,"Gen Y",IF(Table2[[#This Row],[Usia]]<56,"Gen X",IF(Table2[[#This Row],[Usia]]>=56,"Baby Boomer")))) -> Gen Y | L52: D3 | N52: 2.46 | O52: 2.81 | P52: 4.86 | Q52: 1.1 | R52: 4.53 | S52: 1.76 | T52: 1.14 | U52: 3.85 | V52: 4.51 | W52: 3.17 | X52: 4.59 | Y52: =AVERAGE(Table2[[#This Row],[Jan]:[Dec]]) -> 3.1618182 | Z52: =IF(Table2[[#This Row],[Average]]<3,"Low",IF(Table2[[#This Row],[Average]]<=4,"Med",IF(Table2[[#This Row],[Average]]>4,"High"))) -> Med
A53: 250178 | B53: Kirana Citra Destiyanti | C53: Support | D53: Staff | E53: Jakarta | F53: Permanent | G53: Perempuan | H53: 34138 | I53: 42826 | J53: =DATEDIF(Table2[[#This Row],[Tanggal Lahir]],NOW(),"Y") -> 33 | K53: =IF(Table2[[#This Row],[Usia]]<25,"Gen Z",IF(Table2[[#This Row],[Usia]]<40,"Gen Y",IF(Table2[[#This Row],[Usia]]<56,"Gen X",IF(Table2[[#This Row],[Usia]]>=56,"Baby Boomer")))) -> Gen Y | L53: D3 | M53: 1.74 | N53: 4.92 | O53: 2.08 | P53: 3.72 | Q53: 1.88 | R53: 1.09 | S53: 2.76 | T53: 4.85 | U53: 4.41 | V53: 1.72 | W53: 2.86 | X53: 2.65 | Y53: =AVERAGE(Table2[[#This Row],[Jan]:[Dec]]) -> 2.89 | Z53: =IF(Table2[[#This Row],[Average]]<3,"Low",IF(Table2[[#This Row],[Average]]<=4,"Med",IF(Table2[[#This Row],[Average]]>4,"High"))) -> Low
A54: 252814 | B54: Irfan Adi Pamuji | C54: Bisnis | D54: Staff | E54: Jakarta | F54: Permanent | G54: Laki-laki | H54: 32002 | I54: 42963 | J54: =DATEDIF(Table2[[#This Row],[Tanggal Lahir]],NOW(),"Y") -> 38 | K54: =IF(Table2[[#This Row],[Usia]]<25,"Gen Z",IF(Table2[[#This Row],[Usia]]<40,"Gen Y",IF(Table2[[#This Row],[Usia]]<56,"Gen X",IF(Table2[[#This Row],[Usia]]>=56,"Baby Boomer")))) -> Gen Y | L54: D3 | M54: 4.12 | N54: 1.51 | O54: 4.33 | P54: 3.86 | Q54: 3.96 | R54: 2.14 | S54: 4.19 | T54: 2.25 | U54: 3.44 | V54: 2.34 | W54: 2.31 | X54: 3.89 | Y54: =AVERAGE(Table2[[#This Row],[Jan]:[Dec]]) -> 3.195 | Z54: =IF(Table2[[#This Row],[Average]]<3,"Low",IF(Table2[[#This Row],[Average]]<=4,"Med",IF(Table2[[#This Row],[Average]]>4,"High"))) -> Med
A55: 254140 | B55: Dwi Laksana Bhakti | C55: Bisnis | D55: Staff | E55: Jakarta | F55: Contract | G55: Laki-laki | H55: 34181 | I55: 44531 | J55: =DATEDIF(Table2[[#This Row],[Tanggal Lahir]],NOW(),"Y") -> 33 | K55: =IF(Table2[[#This Row],[Usia]]<25,"Gen Z",IF(Table2[[#This Row],[Usia]]<40,"Gen Y",IF(Table2[[#This Row],[Usia]]<56,"Gen X",IF(Table2[[#This Row],[Usia]]>=56,"Baby Boomer")))) -> Gen Y | L55: SMA | M55: 2.47 | N55: 1.52 | O55: 1.8 | P55: 3.1 | Q55: 4.98 | R55: 4.43 | S55: 4.08 | T55: 3.44 | U55: 4 | V55: 4.45 | W55: 2.38 | X55: 4.01 | Y55: =AVERAGE(Table2[[#This Row],[Jan]:[Dec]]) -> 3.3883333 | Z55: =IF(Table2[[#This Row],[Average]]<3,"Low",IF(Table2[[#This Row],[Average]]<=4,"Med",IF(Table2[[#This Row],[Average]]>4,"High"))) -> Med
A56: 257907 | B56: Dwi Putri Januari | C56: Bisnis | D56: Staff | E56: Jakarta | F56: Permanent | G56: Perempuan | H56: 33826 | I56: 41948 | J56: =DATEDIF(Table2[[#This Row],[Tanggal Lahir]],NOW(),"Y") -> 34 | K56: =IF(Table2[[#This Row],[Usia]]<25,"Gen Z",IF(Table2[[#This Row],[Usia]]<40,"Gen Y",IF(Table2[[#This Row],[Usia]]<56,"Gen X",IF(Table2[[#This Row],[Usia]]>=56,"Baby Boomer")))) -> Gen Y | L56: S1 | M56: 2.57 | N56: 3.34 | O56: 3.1 | P56: 2.66 | Q56: 2.15 | R56: 4.32 | S56: 3.04 | T56: 2.77 | U56: 4.82 | V56: 4.35 | W56: 1.79 | X56: 4.02 | Y56: =AVERAGE(Table2[[#This Row],[Jan]:[Dec]]) -> 3.2441667 | Z56: =IF(Table2[[#This Row],[Average]]<3,"Low",IF(Table2[[#This Row],[Average]]<=4,"Med",IF(Table2[[#This Row],[Average]]>4,"High"))) -> Med
A57: 262261 | B57: Ridwan Raynaldi Putra | C57: Support | D57: Support Staff | E57: Bandung | F57: Outsource | G57: Laki-laki | H57: 31469 | I57: 40112 | J57: =DATEDIF(Table2[[#This Row],[Tanggal Lahir]],NOW(),"Y") -> 40 | K57: =IF(Table2[[#This Row],[Usia]]<25,"Gen Z",IF(Table2[[#This Row],[Usia]]<40,"Gen Y",IF(Table2[[#This Row],[Usia]]<56,"Gen X",IF(Table2[[#This Row],[Usia]]>=56,"Baby Boomer")))) -> Gen X | L57: Diploma | M57: 1.52 | N57: 1.64 | O57: 4.19 | P57: 3.8 | Q57: 4.67 | R57: 4.76 | S57: 2 | T57: 2.55 | U57: 4.17 | V57: 1.05 | W57: 1.28 | X57: 3.1 | Y57: =AVERAGE(Table2[[#This Row],[Jan]:[Dec]]) -> 2.8941667 | Z57: =IF(Table2[[#This Row],[Average]]<3,"Low",IF(Table2[[#This Row],[Average]]<=4,"Med",IF(Table2[[#This Row],[Average]]>4,"High"))) -> Low
A58: 263825 | B58: Muhammad Rizki Alhafizh | C58: Bisnis | D58: Staff | E58: Jakarta | F58: Permanent | G58: Laki-laki | H58: 32972 | I58: 42948 | J58: =DATEDIF(Table2[[#This Row],[Tanggal Lahir]],NOW(),"Y") -> 36 | K58: =IF(Table2[[#This Row],[Usia]]<25,"Gen Z",IF(Table2[[#This Row],[Usia]]<40,"Gen Y",IF(Table2[[#This Row],[Usia]]<56,"Gen X",IF(Table2[[#This Row],[Usia]]>=56,"Baby Boomer")))) -> Gen Y | L58: S1 | M58: 1.32 | N58: 3.31 | O58: 3.42 | P58: 4.86 | Q58: 4.02 | R58: 2.55 | S58: 4.09 | T58: 4.84 | U58: 4.42 | V58: 1.39 | W58: 4.03 | X58: 1.49 | Y58: =AVERAGE(Table2[[#This Row],[Jan]:[Dec]]) -> 3.3116667 | Z58: =IF(Table2[[#This Row],[Average]]<3,"Low",IF(Table2[[#This Row],[Average]]<=4,"Med",IF(Table2[[#This Row],[Average]]>4,"High"))) -> Med
A59: 264056 | B59: Delsa Satya Pratama | C59: Bisnis | D59: Staff | E59: Bandung | F59: Permanent | G59: Laki-laki | H59: 33578 | I59: 42917 | J59: =DATEDIF(Table2[[#This Row],[Tanggal Lahir]],NOW(),"Y") -> 34 | K59: =IF(Table2[[#This Row],[Usia]]<25,"Gen Z",IF(Table2[[#This Row],[Usia]]<40,"Gen Y",IF(Table2[[#This Row],[Usia]]<56,"Gen X",IF(Table2[[#This Row],[Usia]]>=56,"Baby Boomer")))) -> Gen Y | L59: S1 | M59: 3.27 | N59: 2.72 | O59: 3.1 | P59: 1.93 | Q59: 4.32 | R59: 2.91 | S59: 4.38 | T59: 4.61 | U59: 2.25 | V59: 4.96 | W59: 1.47 | X59: 4.69 | Y59: =AVERAGE(Table2[[#This Row],[Jan]:[Dec]]) -> 3.3841667 | Z59: =IF(Table2[[#This Row],[Average]]<3,"Low",IF(Table2[[#This Row],[Average]]<=4,"Med",IF(Table2[[#This Row],[Average]]>4,"High"))) -> Med
A60: 265747 | B60: Dinda Sapta Carolina | C60: Support | D60: Staff | E60: Jakarta | F60: Contract | G60: Perempuan | H60: 34652 | I60: 44239 | J60: =DATEDIF(Table2[[#This Row],[Tanggal Lahir]],NOW(),"Y") -> 31 | K60: =IF(Table2[[#This Row],[Usia]]<25,"Gen Z",IF(Table2[[#This Row],[Usia]]<40,"Gen Y",IF(Table2[[#This Row],[Usia]]<56,"Gen X",IF(Table2[[#This Row],[Usia]]>=56,"Baby Boomer")))) -> Gen Y | L60: S1 | M60: 1.9 | N60: 4.36 | O60: 1.91 | P60: 1.02 | Q60: 3.86 | R60: 3.09 | S60: 1.79 | T60: 2.79 | U60: 1.05 | V60: 3.61 | W60: 4.12 | X60: 4.15 | Y60: =AVERAGE(Table2[[#This Row],[Jan]:[Dec]]) -> 2.8041667 | Z60: =IF(Table2[[#This Row],[Average]]<3,"Low",IF(Table2[[#This Row],[Average]]<=4,"Med",IF(Table2[[#This Row],[Average]]>4,"High"))) -> Low
A61: 266726 | B61: Windi Ayu | C61: Bisnis | D61: Staff | E61: Jakarta | F61: Permanent | G61: Perempuan | H61: 32547 | I61: 43101 | J61: =DATEDIF(Table2[[#This Row],[Tanggal Lahir]],NOW(),"Y") -> 37 | K61: =IF(Table2[[#This Row],[Usia]]<25,"Gen Z",IF(Table2[[#This Row],[Usia]]<40,"Gen Y",IF(Table2[[#This Row],[Usia]]<56,"Gen X",IF(Table2[[#This Row],[Usia]]>=56,"Baby Boomer")))) -> Gen Y | L61: S1 | M61: 1.59 | N61: 3.26 | O61: 2.04 | P61: 4.99 | Q61: 1.51 | R61: 4.6 | S61: 2.18 | T61: 3.83 | U61: 1.41 | V61: 1.3 | W61: 2.04 | X61: 1.3 | Y61: =AVERAGE(Table2[[#This Row],[Jan]:[Dec]]) -> 2.5041667 | Z61: =IF(Table2[[#This Row],[Average]]<3,"Low",IF(Table2[[#This Row],[Average]]<=4,"Med",IF(Table2[[#This Row],[Average]]>4,"High"))) -> Low
A62: 273855 | B62: Ristya Ariyani | C62: Bisnis | D62: Staff | E62: Bandung | F62: Permanent | G62: Perempuan | H62: 30297 | I62: 42917 | J62: =DATEDIF(Table2[[#This Row],[Tanggal Lahir]],NOW(),"Y") -> 43 | K62: =IF(Table2[[#This Row],[Usia]]<25,"Gen Z",IF(Table2[[#This Row],[Usia]]<40,"Gen Y",IF(Table2[[#This Row],[Usia]]<56,"Gen X",IF(Table2[[#This Row],[Usia]]>=56,"Baby Boomer")))) -> Gen X | L62: Diploma | M62: 3.91 | N62: 4.81 | O62: 3.15 | P62: 2.99 | Q62: 1.89 | R62: 1.18 | S62: 4.67 | T62: 2.49 | U62: 4.51 | V62: 4.66 | W62: 4.53 | X62: 1.45 | Y62: =AVERAGE(Table2[[#This Row],[Jan]:[Dec]]) -> 3.3533333 | Z62: =IF(Table2[[#This Row],[Average]]<3,"Low",IF(Table2[[#This Row],[Average]]<=4,"Med",IF(Table2[[#This Row],[Average]]>4,"High"))) -> Med
A63: 275704 | B63: Denis Muhammad Irfan | C63: Bisnis | D63: Staff | E63: Jakarta | F63: Permanent | G63: Laki-laki | H63: 31661 | I63: 40348 | J63: =DATEDIF(Table2[[#This Row],[Tanggal Lahir]],NOW(),"Y") -> 39 | K63: =IF(Table2[[#This Row],[Usia]]<25,"Gen Z",IF(Table2[[#This Row],[Usia]]<40,"Gen Y",IF(Table2[[#This Row],[Usia]]<56,"Gen X",IF(Table2[[#This Row],[Usia]]>=56,"Baby Boomer")))) -> Gen Y | L63: S1 | M63: 1.73 | N63: 4.08 | O63: 2.44 | P63: 1.26 | Q63: 3.5 | R63: 3.37 | S63: 3.98 | T63: 3.28 | U63: 3.96 | V63: 3.75 | W63: 3.33 | X63: 2.79 | Y63: =AVERAGE(Table2[[#This Row],[Jan]:[Dec]]) -> 3.1225 | Z63: =IF(Table2[[#This Row],[Average]]<3,"Low",IF(Table2[[#This Row],[Average]]<=4,"Med",IF(Table2[[#This Row],[Average]]>4,"High"))) -> Med
A64: 276416 | B64: Mariam Marianti | C64: Support | D64: Officer | E64: Jakarta | F64: Permanent | G64: Perempuan | H64: 34084 | I64: 41730 | J64: =DATEDIF(Table2[[#This Row],[Tanggal Lahir]],NOW(),"Y") -> 33 | K64: =IF(Table2[[#This Row],[Usia]]<25,"Gen Z",IF(Table2[[#This Row],[Usia]]<40,"Gen Y",IF(Table2[[#This Row],[Usia]]<56,"Gen X",IF(Table2[[#This Row],[Usia]]>=56,"Baby Boomer")))) -> Gen Y | L64: D3 | M64: 2.02 | N64: 1.17 | O64: 4.16 | P64: 3.9 | Q64: 3.27 | R64: 1.22 | S64: 4.16 | T64: 2.36 | U64: 3.15 | V64: 3.23 | W64: 1.32 | X64: 4.39 | Y64: =AVERAGE(Table2[[#This Row],[Jan]:[Dec]]) -> 2.8625 | Z64: =IF(Table2[[#This Row],[Average]]<3,"Low",IF(Table2[[#This Row],[Average]]<=4,"Med",IF(Table2[[#This Row],[Average]]>4,"High"))) -> Low
... A84: 310044 | B84: Adnan Saefulloh | C84: Support | D84: Staff | E84: Bandung | F84: Contract | G84: Laki-laki | H84: 34496 | I84: 44743 | J84: =DATEDIF(Table2[[#This Row],[Tanggal Lahir]],NOW(),"Y") -> 32 | K84: =IF(Table2[[#This Row],[Usia]]<25,"Gen Z",IF(Table2[[#This Row],[Usia]]<40,"Gen Y",IF(Table2[[#This Row],[Usia]]<56,"Gen X",IF(Table2[[#This Row],[Usia]]>=56,"Baby Boomer")))) -> Gen Y | L84: S1 | M84: 2.21 | N84: 4.13 | O84: 4.59 | P84: 2.36 | Q84: 4.95 | R84: 3.46 | S84: 2.02 | T84: 2.67 | U84: 1.61 | V84: 1.92 | W84: 3.9 | X84: 4.47 | Y84: =AVERAGE(Table2[[#This Row],[Jan]:[Dec]]) -> 3.1908333 | Z84: =IF(Table2[[#This Row],[Average]]<3,"Low",IF(Table2[[#This Row],[Average]]<=4,"Med",IF(Table2[[#This Row],[Average]]>4,"High"))) -> Med
A85: 311002 | B85: Ajeng Gerhana Wulan | C85: Bisnis | D85: Staff | E85: Jakarta | F85: Contract | G85: Perempuan | H85: 37368 | I85: 45108 | J85: =DATEDIF(Table2[[#This Row],[Tanggal Lahir]],NOW(),"Y") -> 24 | K85: =IF(Table2[[#This Row],[Usia]]<25,"Gen Z",IF(Table2[[#This Row],[Usia]]<40,"Gen Y",IF(Table2[[#This Row],[Usia]]<56,"Gen X",IF(Table2[[#This Row],[Usia]]>=56,"Baby Boomer")))) -> Gen Z | L85: SMA | S85: 4.52 | T85: 4.72 | U85: 4.76 | V85: 2.1 | W85: 4.91 | X85: 3.95 | Y85: =AVERAGE(Table2[[#This Row],[Jan]:[Dec]]) -> 4.16 | Z85: =IF(Table2[[#This Row],[Average]]<3,"Low",IF(Table2[[#This Row],[Average]]<=4,"Med",IF(Table2[[#This Row],[Average]]>4,"High"))) -> High
A86: 317929 | B86: Ana Muslimah | C86: Asset | D86: Staff | E86: Jakarta | F86: Permanent | G86: Perempuan | H86: 33889 | I86: 42736 | J86: =DATEDIF(Table2[[#This Row],[Tanggal Lahir]],NOW(),"Y") -> 33 | K86: =IF(Table2[[#This Row],[Usia]]<25,"Gen Z",IF(Table2[[#This Row],[Usia]]<40,"Gen Y",IF(Table2[[#This Row],[Usia]]<56,"Gen X",IF(Table2[[#This Row],[Usia]]>=56,"Baby Boomer")))) -> Gen Y | L86: D3 | M86: 3.08 | N86: 2.45 | O86: 3.3 | P86: 2.28 | Q86: 4.72 | R86: 1.59 | S86: 3.29 | T86: 2.67 | U86: 4.55 | V86: 4.41 | W86: 4.94 | X86: 3.58 | Y86: =AVERAGE(Table2[[#This Row],[Jan]:[Dec]]) -> 3.405 | Z86: =IF(Table2[[#This Row],[Average]]<3,"Low",IF(Table2[[#This Row],[Average]]<=4,"Med",IF(Table2[[#This Row],[Average]]>4,"High"))) -> Med
A87: 320993 | B87: Avrialy Kosvi | C87: Bisnis | D87: Staff | E87: Bandung | F87: Permanent | G87: Laki-laki | H87: 34257 | I87: 42887 | J87: =DATEDIF(Table2[[#This Row],[Tanggal Lahir]],NOW(),"Y") -> 32 | K87: =IF(Table2[[#This Row],[Usia]]<25,"Gen Z",IF(Table2[[#This Row],[Usia]]<40,"Gen Y",IF(Table2[[#This Row],[Usia]]<56,"Gen X",IF(Table2[[#This Row],[Usia]]>=56,"Baby Boomer")))) -> Gen Y | L87: S1 | M87: 4.77 | N87: 2.47 | O87: 3.6 | P87: 2.72 | Q87: 3.6 | R87: 4.11 | S87: 4.21 | T87: 3.35 | U87: 3.61 | V87: 2.68 | W87: 1.57 | X87: 3.9 | Y87: =AVERAGE(Table2[[#This Row],[Jan]:[Dec]]) -> 3.3825 | Z87: =IF(Table2[[#This Row],[Average]]<3,"Low",IF(Table2[[#This Row],[Average]]<=4,"Med",IF(Table2[[#This Row],[Average]]>4,"High"))) -> Med
A88: 324416 | B88: Annisa Maretiamy | C88: Bisnis | D88: Staff | E88: Jakarta | F88: Permanent | G88: Perempuan | H88: 33349 | I88: 41478 | J88: =DATEDIF(Table2[[#This Row],[Tanggal Lahir]],NOW(),"Y") -> 35 | K88: =IF(Table2[[#This Row],[Usia]]<25,"Gen Z",IF(Table2[[#This Row],[Usia]]<40,"Gen Y",IF(Table2[[#This Row],[Usia]]<56,"Gen X",IF(Table2[[#This Row],[Usia]]>=56,"Baby Boomer")))) -> Gen Y | L88: D3 | M88: 4.99 | N88: 2.76 | O88: 3.96 | P88: 3.3 | Q88: 2.21 | R88: 4.85 | S88: 2.23 | T88: 3.5 | U88: 4.83 | V88: 1.5 | W88: 3.31 | X88: 4.74 | Y88: =AVERAGE(Table2[[#This Row],[Jan]:[Dec]]) -> 3.515 | Z88: =IF(Table2[[#This Row],[Average]]<3,"Low",IF(Table2[[#This Row],[Average]]<=4,"Med",IF(Table2[[#This Row],[Average]]>4,"High"))) -> Med
A89: 334019 | B89: Winda Ayulia Agustina | C89: Bisnis | D89: Staff | E89: Bandung | F89: Contract | G89: Perempuan | H89: 35074 | I89: 45078 | J89: =DATEDIF(Table2[[#This Row],[Tanggal Lahir]],NOW(),"Y") -> 30 | K89: =IF(Table2[[#This Row],[Usia]]<25,"Gen Z",IF(Table2[[#This Row],[Usia]]<40,"Gen Y",IF(Table2[[#This Row],[Usia]]<56,"Gen X",IF(Table2[[#This Row],[Usia]]>=56,"Baby Boomer")))) -> Gen Y | L89: S1 | R89: 4.77 | S89: 1.18 | T89: 2.56 | U89: 2.49 | V89: 4.38 | W89: 4.53 | X89: 1.89 | Y89: =AVERAGE(Table2[[#This Row],[Jan]:[Dec]]) -> 3.1142857 | Z89: =IF(Table2[[#This Row],[Average]]<3,"Low",IF(Table2[[#This Row],[Average]]<=4,"Med",IF(Table2[[#This Row],[Average]]>4,"High"))) -> Med
A90: 335361 | B90: Anisa Ayu Parwati | C90: Bisnis | D90: Staff | E90: Jakarta | F90: Contract | G90: Perempuan | H90: 33462 | I90: 43891 | J90: =DATEDIF(Table2[[#This Row],[Tanggal Lahir]],NOW(),"Y") -> 34 | K90: =IF(Table2[[#This Row],[Usia]]<25,"Gen Z",IF(Table2[[#This Row],[Usia]]<40,"Gen Y",IF(Table2[[#This Row],[Usia]]<56,"Gen X",IF(Table2[[#This Row],[Usia]]>=56,"Baby Boomer")))) -> Gen Y | L90: S1 | M90: 4.63 | N90: 4.86 | O90: 1.84 | P90: 1.8 | Q90: 1.53 | R90: 1.58 | S90: 4.55 | T90: 3.24 | U90: 3.07 | V90: 1.55 | W90: 4.72 | X90: 1.76 | Y90: =AVERAGE(Table2[[#This Row],[Jan]:[Dec]]) -> 2.9275 | Z90: =IF(Table2[[#This Row],[Average]]<3,"Low",IF(Table2[[#This Row],[Average]]<=4,"Med",IF(Table2[[#This Row],[Average]]>4,"High"))) -> Low
A91: 336911 | B91: Suci Wulan Sari | C91: Bisnis | D91: Staff | E91: Jakarta | F91: Contract | G91: Perempuan | H91: 33548 | I91: 44470 | J91: =DATEDIF(Table2[[#This Row],[Tanggal Lahir]],NOW(),"Y") -> 34 | K91: =IF(Table2[[#This Row],[Usia]]<25,"Gen Z",IF(Table2[[#This Row],[Usia]]<40,"Gen Y",IF(Table2[[#This Row],[Usia]]<56,"Gen X",IF(Table2[[#This Row],[Usia]]>=56,"Baby Boomer")))) -> Gen Y | L91: S1 | M91: 4.72 | N91: 3.73 | O91: 3.98 | P91: 1.93 | Q91: 1.31 | R91: 1.27 | S91: 4.82 | T91: 1.35 | U91: 1.42 | V91: 4.43 | W91: 3.94 | X91: 3.52 | Y91: =AVERAGE(Table2[[#This Row],[Jan]:[Dec]]) -> 3.035 | Z91: =IF(Table2[[#This Row],[Average]]<3,"Low",IF(Table2[[#This Row],[Average]]<=4,"Med",IF(Table2[[#This Row],[Average]]>4,"High"))) -> Med
A92: 336953 | B92: Ninne Nuraida | C92: Managerial | D92: Manager | E92: Bandung | F92: Permanent | G92: Perempuan | H92: 29810 | I92: 38596 | J92: =DATEDIF(Table2[[#This Row],[Tanggal Lahir]],NOW(),"Y") -> 44 | K92: =IF(Table2[[#This Row],[Usia]]<25,"Gen Z",IF(Table2[[#This Row],[Usia]]<40,"Gen Y",IF(Table2[[#This Row],[Usia]]<56,"Gen X",IF(Table2[[#This Row],[Usia]]>=56,"Baby Boomer")))) -> Gen X | L92: S1 | M92: 4.9 | N92: 1.36 | O92: 4.44 | P92: 4.54 | Q92: 2.69 | R92: 4.08 | S92: 1.31 | T92: 1.81 | U92: 3.18 | V92: 2.33 | W92: 1.24 | X92: 4.88 | Y92: =AVERAGE(Table2[[#This Row],[Jan]:[Dec]]) -> 3.0633333 | Z92: =IF(Table2[[#This Row],[Average]]<3,"Low",IF(Table2[[#This Row],[Average]]<=4,"Med",IF(Table2[[#This Row],[Average]]>4,"High"))) -> Med
A93: 345274 | B93: Andrian Kusnadi | C93: Bisnis | D93: Staff | E93: Bandung | F93: Permanent | G93: Laki-laki | H93: 34259 | I93: 42887 | J93: =DATEDIF(Table2[[#This Row],[Tanggal Lahir]],NOW(),"Y") -> 32 | K93: =IF(Table2[[#This Row],[Usia]]<25,"Gen Z",IF(Table2[[#This Row],[Usia]]<40,"Gen Y",IF(Table2[[#This Row],[Usia]]<56,"Gen X",IF(Table2[[#This Row],[Usia]]>=56,"Baby Boomer")))) -> Gen Y | L93: S1 | M93: 4.34 | N93: 3.83 | O93: 3.04 | P93: 4.61 | Q93: 1.38 | R93: 1.97 | S93: 3.9 | T93: 2.8 | U93: 1.38 | V93: 4.14 | W93: 1.31 | X93: 3.32 | Y93: =AVERAGE(Table2[[#This Row],[Jan]:[Dec]]) -> 3.0016667 | Z93: =IF(Table2[[#This Row],[Average]]<3,"Low",IF(Table2[[#This Row],[Average]]<=4,"Med",IF(Table2[[#This Row],[Average]]>4,"High"))) -> Med
A94: 345929 | B94: Neneng Royani | C94: Bisnis | D94: Staff | E94: Bandung | F94: Permanent | G94: Perempuan | H94: 29394 | I94: 39479 | J94: =DATEDIF(Table2[[#This Row],[Tanggal Lahir]],NOW(),"Y") -> 46 | K94: =IF(Table2[[#This Row],[Usia]]<25,"Gen Z",IF(Table2[[#This Row],[Usia]]<40,"Gen Y",IF(Table2[[#This Row],[Usia]]<56,"Gen X",IF(Table2[[#This Row],[Usia]]>=56,"Baby Boomer")))) -> Gen X | L94: S1 | M94: 1.07 | N94: 2 | O94: 1.05 | P94: 3.97 | Q94: 3.68 | R94: 2.36 | S94: 4.38 | T94: 4.59 | U94: 2.8 | V94: 1.7 | W94: 1.39 | X94: 3.91 | Y94: =AVERAGE(Table2[[#This Row],[Jan]:[Dec]]) -> 2.7416667 | Z94: =IF(Table2[[#This Row],[Average]]<3,"Low",IF(Table2[[#This Row],[Average]]<=4,"Med",IF(Table2[[#This Row],[Average]]>4,"High"))) -> Low
A95: 348338 | B95: Widi Dwi Adhawati | C95: Bisnis | D95: Staff | E95: Jakarta | F95: Permanent | G95: Perempuan | H95: 32577 | I95: 40603 | J95: =DATEDIF(Table2[[#This Row],[Tanggal Lahir]],NOW(),"Y") -> 37 | K95: =IF(Table2[[#This Row],[Usia]]<25,"Gen Z",IF(Table2[[#This Row],[Usia]]<40,"Gen Y",IF(Table2[[#This Row],[Usia]]<56,"Gen X",IF(Table2[[#This Row],[Usia]]>=56,"Baby Boomer")))) -> Gen Y | L95: S1 | M95: 2.16 | N95: 3.08 | O95: 4.01 | P95: 1.46 | Q95: 1.84 | R95: 4.65 | S95: 3.69 | T95: 1.22 | U95: 4.57 | V95: 2.51 | W95: 3.22 | X95: 4.53 | Y95: =AVERAGE(Table2[[#This Row],[Jan]:[Dec]]) -> 3.0783333 | Z95: =IF(Table2[[#This Row],[Average]]<3,"Low",IF(Table2[[#This Row],[Average]]<=4,"Med",IF(Table2[[#This Row],[Average]]>4,"High"))) -> Med
A96: 353044 | B96: Annisa Dessetiani Lee | C96: Bisnis | D96: Officer | E96: Bandung | F96: Permanent | G96: Perempuan | H96: 30925 | I96: 41883 | J96: =DATEDIF(Table2[[#This Row],[Tanggal Lahir]],NOW(),"Y") -> 41 | K96: =IF(Table2[[#This Row],[Usia]]<25,"Gen Z",IF(Table2[[#This Row],[Usia]]<40,"Gen Y",IF(Table2[[#This Row],[Usia]]<56,"Gen X",IF(Table2[[#This Row],[Usia]]>=56,"Baby Boomer")))) -> Gen X | L96: S1 | M96: 4.6 | N96: 4.06 | O96: 1.61 | P96: 1.3 | Q96: 1.92 | R96: 4.03 | S96: 2.44 | T96: 3.65 | U96: 4.58 | V96: 1.99 | W96: 1.54 | X96: 3.38 | Y96: =AVERAGE(Table2[[#This Row],[Jan]:[Dec]]) -> 2.925 | Z96: =IF(Table2[[#This Row],[Average]]<3,"Low",IF(Table2[[#This Row],[Average]]<=4,"Med",IF(Table2[[#This Row],[Average]]>4,"High"))) -> Low
...
